{"uuid": "960b8ba6-d97b-4fa8-9f6b-b7bce8762fb9", "counter": 21, "stdout": "\u001b[0;31mfatal: [localhost]: FAILED! => {\"changed\": false, \"module_stderr\": \"ModuleNotFoundError: No module named '_cffi_backend'\\nthread '<unnamed>' panicked at /github/home/.cargo/registry/src/index.crates.io-6f17d22bba15001f/pyo3-0.20.3/src/err/mod.rs:788:5:\\nPython API call failed\\nnote: run with `RUST_BACKTRACE=1` environment variable to display a backtrace\\nTraceback (most recent call last):\\n  File \\\"/home/codespace/.ansible/tmp/ansible-tmp-1711331539.9021926-19733-113812890255973/AnsiballZ_apt.py\\\", line 107, in <module>\\n    _ansiballz_main()\\n  File \\\"/home/codespace/.ansible/tmp/ansible-tmp-1711331539.9021926-19733-113812890255973/AnsiballZ_apt.py\\\", line 99, in _ansiballz_main\\n    invoke_module(zipped_mod, temp_path, ANSIBALLZ_PARAMS)\\n  File \\\"/home/codespace/.ansible/tmp/ansible-tmp-1711331539.9021926-19733-113812890255973/AnsiballZ_apt.py\\\", line 47, in invoke_module\\n    runpy.run_module(mod_name='ansible.modules.apt', init_globals=dict(_module_fqn='ansible.modules.apt', _modlib_path=modlib_path),\\n  File \\\"/usr/local/python/3.10.13/lib/python3.10/runpy.py\\\", line 224, in run_module\\n    return _run_module_code(code, init_globals, run_name, mod_spec)\\n  File \\\"/usr/local/python/3.10.13/lib/python3.10/runpy.py\\\", line 96, in _run_module_code\\n    _run_code(code, mod_globals, init_globals,\\n  File \\\"/usr/local/python/3.10.13/lib/python3.10/runpy.py\\\", line 86, in _run_code\\n    exec(code, run_globals)\\n  File \\\"/tmp/ansible_apt_payload_zvffnqmf/ansible_apt_payload.zip/ansible/modules/apt.py\\\", line 377, in <module>\\n  File \\\"/tmp/ansible_apt_payload_zvffnqmf/ansible_apt_payload.zip/ansible/module_utils/urls.py\\\", line 190, in <module>\\n  File \\\"/usr/local/python/3.10.13/lib/python3.10/site-packages/cryptography/x509/__init__.py\\\", line 7, in <module>\\n    from cryptography.x509 import certificate_transparency, verification\\n  File \\\"/usr/local/python/3.10.13/lib/python3.10/site-packages/cryptography/x509/certificate_transparency.py\\\", line 11, in <module>\\n    from cryptography.hazmat.bindings._rust import x509 as rust_x509\\npyo3_runtime.PanicException: Python API call failed\\n\", \"module_stdout\": \"\", \"msg\": \"MODULE FAILURE\\nSee stdout/stderr for the exact error\", \"rc\": 1}\u001b[0m", "start_line": 22, "end_line": 23, "runner_ident": "b6fca5ee-e1ee-4bd0-8786-82e5d737aedf", "event": "runner_on_failed", "pid": 19636, "created": "2024-03-25T01:52:20.298903", "parent_uuid": "0022487d-654a-a665-bb2c-000000000010", "event_data": {"playbook": "./hello.yml", "playbook_uuid": "66fe1009-df52-4090-8e74-040fd8a119a4", "play": "Play - Install and configure Nginx as a LoadBalancer", "play_uuid": "0022487d-654a-a665-bb2c-00000000000e", "play_pattern": "localhost", "task": "Update cache", "task_uuid": "0022487d-654a-a665-bb2c-000000000010", "task_action": "apt", "resolved_action": "ansible.builtin.apt", "task_args": "", "task_path": "/workspaces/ensf400-lab5-ansible/hello.yml:65", "host": "localhost", "remote_addr": "127.0.0.1", "res": {"module_stdout": "", "module_stderr": "ModuleNotFoundError: No module named '_cffi_backend'\nthread '<unnamed>' panicked at /github/home/.cargo/registry/src/index.crates.io-6f17d22bba15001f/pyo3-0.20.3/src/err/mod.rs:788:5:\nPython API call failed\nnote: run with `RUST_BACKTRACE=1` environment variable to display a backtrace\nTraceback (most recent call last):\n  File \"/home/codespace/.ansible/tmp/ansible-tmp-1711331539.9021926-19733-113812890255973/AnsiballZ_apt.py\", line 107, in <module>\n    _ansiballz_main()\n  File \"/home/codespace/.ansible/tmp/ansible-tmp-1711331539.9021926-19733-113812890255973/AnsiballZ_apt.py\", line 99, in _ansiballz_main\n    invoke_module(zipped_mod, temp_path, ANSIBALLZ_PARAMS)\n  File \"/home/codespace/.ansible/tmp/ansible-tmp-1711331539.9021926-19733-113812890255973/AnsiballZ_apt.py\", line 47, in invoke_module\n    runpy.run_module(mod_name='ansible.modules.apt', init_globals=dict(_module_fqn='ansible.modules.apt', _modlib_path=modlib_path),\n  File \"/usr/local/python/3.10.13/lib/python3.10/runpy.py\", line 224, in run_module\n    return _run_module_code(code, init_globals, run_name, mod_spec)\n  File \"/usr/local/python/3.10.13/lib/python3.10/runpy.py\", line 96, in _run_module_code\n    _run_code(code, mod_globals, init_globals,\n  File \"/usr/local/python/3.10.13/lib/python3.10/runpy.py\", line 86, in _run_code\n    exec(code, run_globals)\n  File \"/tmp/ansible_apt_payload_zvffnqmf/ansible_apt_payload.zip/ansible/modules/apt.py\", line 377, in <module>\n  File \"/tmp/ansible_apt_payload_zvffnqmf/ansible_apt_payload.zip/ansible/module_utils/urls.py\", line 190, in <module>\n  File \"/usr/local/python/3.10.13/lib/python3.10/site-packages/cryptography/x509/__init__.py\", line 7, in <module>\n    from cryptography.x509 import certificate_transparency, verification\n  File \"/usr/local/python/3.10.13/lib/python3.10/site-packages/cryptography/x509/certificate_transparency.py\", line 11, in <module>\n    from cryptography.hazmat.bindings._rust import x509 as rust_x509\npyo3_runtime.PanicException: Python API call failed\n", "msg": "MODULE FAILURE\nSee stdout/stderr for the exact error", "rc": 1, "_ansible_no_log": false, "changed": false}, "start": "2024-03-25T01:52:19.887544", "end": "2024-03-25T01:52:20.298654", "duration": 0.41111, "ignore_errors": null, "event_loop": null, "uuid": "960b8ba6-d97b-4fa8-9f6b-b7bce8762fb9"}}